<?xml version="1.0" ?>
<robot name="Robot">
  <!--Generated by CROSS, a ROS Workbench for FreeCAD (https://github.com/galou/freecad.cross)-->
  <link name="Link_chassis">
    <visual>
      <!--chassis/Body.-->
      <origin xyz="0.0 0.0 0.0" rpy="0.0 -0.0 0.0"/>
      <geometry>
        <mesh filename="package://robot_ffc_1/meshes/Unnamed_Body.dae"/>
      </geometry>
    </visual>
    <collision>
      <!--chassis/Body.-->
      <origin xyz="0.0 0.0 0.0" rpy="0.0 -0.0 0.0"/>
      <geometry>
        <mesh filename="package://robot_ffc_1/meshes/Unnamed_Body.dae"/>
      </geometry>
    </collision>
    <inertial>
      <mass value="0.0742"/>
      <origin xyz="-1.05471e-19 5.37348e-20 0.005" rpy="0.0 -0.0 0.0"/>
      <inertia ixx="3.091666666666666e-05" ixy="-2.64515165326884e-21" ixz="0.0" iyy="6.245166666666667e-05" iyz="9.226397423844905e-24" izz="9.213166666666668e-05"/>
    </inertial>
  </link>
  <link name="Link_w_fr">
    <visual>
      <!--wheel/Body001.-->
      <origin xyz="0.0 0.0 0.0" rpy="0.0 -0.0 0.0"/>
      <geometry>
        <mesh filename="package://robot_ffc_1/meshes/Unnamed_Body001.dae"/>
      </geometry>
    </visual>
    <collision>
      <!--wheel/Body001.-->
      <origin xyz="0.0 0.0 0.0" rpy="0.0 -0.0 0.0"/>
      <geometry>
        <mesh filename="package://robot_ffc_1/meshes/Unnamed_Body001.dae"/>
      </geometry>
    </collision>
    <inertial>
      <mass value="0.062439153990097154"/>
      <origin xyz="2.47041e-18 8.80126e-20 0.015" rpy="0.0 -0.0 0.0"/>
      <inertia ixx="1.4439054360210115e-05" ixy="-1.8811642955437255e-22" ixz="-8.94651748239994e-22" iyy="1.4439054360209925e-05" iyz="9.228062957291355e-24" izz="1.9512235621905463e-05"/>
    </inertial>
  </link>
  <link name="Link_w_fl">
    <visual>
      <!--wheel/Body001.-->
      <origin xyz="0.0 0.0 0.0" rpy="0.0 -0.0 0.0"/>
      <geometry>
        <mesh filename="package://robot_ffc_1/meshes/Unnamed_Body001.dae"/>
      </geometry>
    </visual>
    <collision>
      <!--wheel/Body001.-->
      <origin xyz="0.0 0.0 0.0" rpy="0.0 -0.0 0.0"/>
      <geometry>
        <mesh filename="package://robot_ffc_1/meshes/Unnamed_Body001.dae"/>
      </geometry>
    </collision>
    <inertial>
      <mass value="0.062439153990097154"/>
      <origin xyz="2.47041e-18 8.80126e-20 0.015" rpy="0.0 -0.0 0.0"/>
      <inertia ixx="1.4439054360210115e-05" ixy="-1.8811642955437255e-22" ixz="-8.94651748239994e-22" iyy="1.4439054360209925e-05" iyz="9.228062957291355e-24" izz="1.9512235621905463e-05"/>
    </inertial>
  </link>
  <link name="Link_w_rr">
    <visual>
      <!--wheel/Body001.-->
      <origin xyz="0.0 0.0 0.0" rpy="0.0 -0.0 0.0"/>
      <geometry>
        <mesh filename="package://robot_ffc_1/meshes/Unnamed_Body001.dae"/>
      </geometry>
    </visual>
    <collision>
      <!--wheel/Body001.-->
      <origin xyz="0.0 0.0 0.0" rpy="0.0 -0.0 0.0"/>
      <geometry>
        <mesh filename="package://robot_ffc_1/meshes/Unnamed_Body001.dae"/>
      </geometry>
    </collision>
    <inertial>
      <mass value="0.062439153990097154"/>
      <origin xyz="2.47041e-18 8.80126e-20 0.015" rpy="0.0 -0.0 0.0"/>
      <inertia ixx="1.4439054360210115e-05" ixy="-1.8811642955437255e-22" ixz="-8.94651748239994e-22" iyy="1.4439054360209925e-05" iyz="9.228062957291355e-24" izz="1.9512235621905463e-05"/>
    </inertial>
  </link>
  <link name="Link_w_rl">
    <visual>
      <!--wheel/Body001.-->
      <origin xyz="0.0 0.0 0.0" rpy="0.0 -0.0 0.0"/>
      <geometry>
        <mesh filename="package://robot_ffc_1/meshes/Unnamed_Body001.dae"/>
      </geometry>
    </visual>
    <collision>
      <!--wheel/Body001.-->
      <origin xyz="0.0 0.0 0.0" rpy="0.0 -0.0 0.0"/>
      <geometry>
        <mesh filename="package://robot_ffc_1/meshes/Unnamed_Body001.dae"/>
      </geometry>
    </collision>
    <inertial>
      <mass value="0.062439153990097154"/>
      <origin xyz="2.47041e-18 8.80126e-20 0.015" rpy="0.0 -0.0 0.0"/>
      <inertia ixx="1.4439054360210115e-05" ixy="-1.8811642955437255e-22" ixz="-8.94651748239994e-22" iyy="1.4439054360209925e-05" iyz="9.228062957291355e-24" izz="1.9512235621905463e-05"/>
    </inertial>
  </link>
  <joint name="Joint_fr" type="continuous">
    <parent link="Link_chassis"/>
    <child link="Link_w_fr"/>
    <origin xyz="0.05 -0.035 0.0" rpy="1.5707963267948966 -0.0 0.0"/>
    <axis xyz="0 0 1"/>
  </joint>
  <joint name="Joint_fl" type="continuous">
    <parent link="Link_chassis"/>
    <child link="Link_w_fl"/>
    <origin xyz="0.05 0.035 0.0" rpy="-1.5707963267948966 0.0 0.0"/>
    <axis xyz="0 0 1"/>
  </joint>
  <joint name="Joint_rr" type="continuous">
    <parent link="Link_chassis"/>
    <child link="Link_w_rr"/>
    <origin xyz="-0.05 -0.035 0.0" rpy="1.5707963267948966 -0.0 0.0"/>
    <axis xyz="0 0 1"/>
  </joint>
  <joint name="Joint_rl" type="continuous">
    <parent link="Link_chassis"/>
    <child link="Link_w_rl"/>
    <origin xyz="-0.05 0.035 0.0" rpy="-1.5707963267948966 0.0 0.0"/>
    <axis xyz="0 0 1"/>
  </joint>
</robot>
